Traceback (most recent call last):
  File "/home/mibur/anaconda3/envs/dfc-multiverse/lib/python3.11/site-packages/jupyter_cache/executors/utils.py", line 58, in single_nb_execution
    executenb(
  File "/home/mibur/anaconda3/envs/dfc-multiverse/lib/python3.11/site-packages/nbclient/client.py", line 1314, in execute
    return NotebookClient(nb=nb, resources=resources, km=km, **kwargs).execute()
           ^^^^^^^^^^^^^^^^^^^^^^^^^^^^^^^^^^^^^^^^^^^^^^^^^^^^^^^^^^^^^^^^^^^^^
  File "/home/mibur/anaconda3/envs/dfc-multiverse/lib/python3.11/site-packages/jupyter_core/utils/__init__.py", line 173, in wrapped
    return loop.run_until_complete(inner)
           ^^^^^^^^^^^^^^^^^^^^^^^^^^^^^^
  File "/home/mibur/anaconda3/envs/dfc-multiverse/lib/python3.11/asyncio/base_events.py", line 653, in run_until_complete
    return future.result()
           ^^^^^^^^^^^^^^^
  File "/home/mibur/anaconda3/envs/dfc-multiverse/lib/python3.11/site-packages/nbclient/client.py", line 709, in async_execute
    await self.async_execute_cell(
  File "/home/mibur/anaconda3/envs/dfc-multiverse/lib/python3.11/site-packages/nbclient/client.py", line 1062, in async_execute_cell
    await self._check_raise_for_error(cell, cell_index, exec_reply)
  File "/home/mibur/anaconda3/envs/dfc-multiverse/lib/python3.11/site-packages/nbclient/client.py", line 918, in _check_raise_for_error
    raise CellExecutionError.from_cell_and_msg(cell, exec_reply_content)
nbclient.exceptions.CellExecutionError: An error occurred while executing the following cell:
------------------
import datetime
print(f"The current date and time are: {datetime.now()}")
------------------


[0;31m---------------------------------------------------------------------------[0m
[0;31mAttributeError[0m                            Traceback (most recent call last)
Cell [0;32mIn[1], line 2[0m
[1;32m      1[0m [38;5;28;01mimport[39;00m [38;5;21;01mdatetime[39;00m
[0;32m----> 2[0m [38;5;28mprint[39m([38;5;124mf[39m[38;5;124m"[39m[38;5;124mThe current date and time are: [39m[38;5;132;01m{[39;00m[43mdatetime[49m[38;5;241;43m.[39;49m[43mnow[49m()[38;5;132;01m}[39;00m[38;5;124m"[39m)

[0;31mAttributeError[0m: module 'datetime' has no attribute 'now'

