Traceback (most recent call last):
  File "/home/mibur/anaconda3/envs/dfc-multiverse/lib/python3.11/site-packages/jupyter_cache/executors/utils.py", line 58, in single_nb_execution
    executenb(
  File "/home/mibur/anaconda3/envs/dfc-multiverse/lib/python3.11/site-packages/nbclient/client.py", line 1314, in execute
    return NotebookClient(nb=nb, resources=resources, km=km, **kwargs).execute()
           ^^^^^^^^^^^^^^^^^^^^^^^^^^^^^^^^^^^^^^^^^^^^^^^^^^^^^^^^^^^^^^^^^^^^^
  File "/home/mibur/anaconda3/envs/dfc-multiverse/lib/python3.11/site-packages/jupyter_core/utils/__init__.py", line 173, in wrapped
    return loop.run_until_complete(inner)
           ^^^^^^^^^^^^^^^^^^^^^^^^^^^^^^
  File "/home/mibur/anaconda3/envs/dfc-multiverse/lib/python3.11/asyncio/base_events.py", line 653, in run_until_complete
    return future.result()
           ^^^^^^^^^^^^^^^
  File "/home/mibur/anaconda3/envs/dfc-multiverse/lib/python3.11/site-packages/nbclient/client.py", line 709, in async_execute
    await self.async_execute_cell(
  File "/home/mibur/anaconda3/envs/dfc-multiverse/lib/python3.11/site-packages/nbclient/client.py", line 1062, in async_execute_cell
    await self._check_raise_for_error(cell, cell_index, exec_reply)
  File "/home/mibur/anaconda3/envs/dfc-multiverse/lib/python3.11/site-packages/nbclient/client.py", line 918, in _check_raise_for_error
    raise CellExecutionError.from_cell_and_msg(cell, exec_reply_content)
nbclient.exceptions.CellExecutionError: An error occurred while executing the following cell:
------------------
scans_per_subject = subjects_total / scans_total
------------------


[0;31m---------------------------------------------------------------------------[0m
[0;31mNameError[0m                                 Traceback (most recent call last)
Cell [0;32mIn[6], line 1[0m
[0;32m----> 1[0m scans_per_subject [38;5;241m=[39m [43msubjects_total[49m [38;5;241m/[39m scans_total

[0;31mNameError[0m: name 'subjects_total' is not defined

